<?xml version="1.0" ?>
<!-- =================================================================================== -->
<!-- |    This document was autogenerated by xacro from urdf/s1.urdf.xacro             | -->
<!-- |    EDITING THIS FILE BY HAND IS NOT RECOMMENDED                                 | -->
<!-- =================================================================================== -->
<robot name="pf1s1">
  <!-- Ground clearance -->
  <link name="base_footprint">
    <visual>
      <geometry>
        <sphere radius="0.001"/>
      </geometry>
    </visual>
  </link>
  <link name="base_link">
    <visual>
      <geometry>
        <box size="0.3 0.2 0.055"/>
      </geometry>
      <origin rpy="0 0 0" xyz="0 0 0"/>
      <material name="baselink_color">
        <color rgba="1.0 0.5 0.2 0.5"/>
      </material>
    </visual>
  </link>
  <joint name="link2footprint" type="fixed">
    <parent link="base_footprint"/>
    <child link="base_link"/>
    <origin xyz="0 0 0.0875"/>
  </joint>
  <link name="left_wheel">
    <visual>
      <geometry>
        <cylinder length="0.027" radius="0.0325"/>
      </geometry>
      <origin rpy="1.5707963 0.0 0.0" xyz="0.0 0.0 0.0"/>
      <material name="black">
        <color rgba="0 0 0 0.5"/>
      </material>
    </visual>
  </link>
  <joint name="left_wheel2link" type="continuous">
    <parent link="base_link"/>
    <child link="left_wheel"/>
    <origin rpy="0 0 0" xyz="0 0.10500000000000001 -0.05499999999999999"/>
    <axis xyz="0 1 0"/>
  </joint>
  <link name="right_wheel">
    <visual>
      <geometry>
        <cylinder length="0.027" radius="0.0325"/>
      </geometry>
      <origin rpy="1.5707963 0.0 0.0" xyz="0.0 0.0 0.0"/>
      <material name="black">
        <color rgba="0 0 0 0.5"/>
      </material>
    </visual>
  </link>
  <joint name="right_wheel2link" type="continuous">
    <parent link="base_link"/>
    <child link="right_wheel"/>
    <origin rpy="0 0 0" xyz="0 -0.10500000000000001 -0.05499999999999999"/>
    <axis xyz="0 1 0"/>
  </joint>
  <link name="front_wheel">
    <visual>
      <geometry>
        <sphere radius="0.025"/>
      </geometry>
      <origin rpy="0 0 0" xyz="0 0 0"/>
      <material name="black">
        <color rgba="0 0 0 0.5"/>
      </material>
    </visual>
  </link>
  <joint name="front_wheel2base_link" type="continuous">
    <parent link="base_link"/>
    <child link="front_wheel"/>
    <origin rpy="0 0 0" xyz="0.09999999999999999 0 -0.0635"/>
    <axis xyz="0 1 0"/>
  </joint>
  <link name="back_wheel">
    <visual>
      <geometry>
        <sphere radius="0.025"/>
      </geometry>
      <origin rpy="0 0 0" xyz="0 0 0"/>
      <material name="black">
        <color rgba="0 0 0 0.5"/>
      </material>
    </visual>
  </link>
  <joint name="back_wheel2base_link" type="continuous">
    <parent link="base_link"/>
    <child link="back_wheel"/>
    <origin rpy="0 0 0" xyz="-0.09999999999999999 0 -0.0635"/>
    <axis xyz="0 1 0"/>
  </joint>
  <link name="camera">
    <visual>
      <geometry>
        <box size="0.005 0.06 0.01"/>
      </geometry>
      <origin rpy="0 0 0" xyz="0 0 0"/>
      <material name="black">
        <color rgba="0 0 0 0.8"/>
      </material>
    </visual>
  </link>
  <joint name="camera2base" type="fixed">
    <parent link="base_link"/>
    <child link="camera"/>
    <origin rpy="0 0 0" xyz="0.16 0 0"/>
  </joint>
  <link name="support">
    <visual>
      <geometry>
        <cylinder length="0.03" radius="0.01"/>
      </geometry>
      <material name="yellow">
        <color rgba="0.8 0.5 0.0 0.5"/>
      </material>
    </visual>
  </link>
  <joint name="support2base" type="fixed">
    <parent link="base_link"/>
    <child link="support"/>
    <origin rpy="0 0 0" xyz="0.07999999999999999 0 0.0275"/>
  </joint>
  <link name="laser">
    <visual>
      <geometry>
        <cylinder length="0.04" radius="0.045"/>
      </geometry>
      <material name="black">
        <color rgba="0 0 0 0.5"/>
      </material>
    </visual>
  </link>
  <joint name="laser2support" type="fixed">
    <parent link="support"/>
    <child link="laser"/>
    <origin rpy="0 0 0" xyz="0 0 0.04"/>
  </joint>
</robot>
